<?xml version="1.0" encoding="UTF-8"?><rss version="2.0"
	xmlns:content="http://purl.org/rss/1.0/modules/content/"
	xmlns:dc="http://purl.org/dc/elements/1.1/"
	xmlns:atom="http://www.w3.org/2005/Atom"
	xmlns:sy="http://purl.org/rss/1.0/modules/syndication/"
	xmlns:georss="http://www.georss.org/georss" xmlns:geo="http://www.w3.org/2003/01/geo/wgs84_pos#" 
	>
<channel>
	<title>Comments on: &#8220;BlockingIOError: [Errno 11] Resource temporarily unavailable&#8221; pour Python 3.6</title>
	<atom:link href="http://sametmax.com/blockingioerror-errno-11-resource-temporarily-unavailable-pour-python-3-6/feed/" rel="self" type="application/rss+xml" />
	<link>http://sametmax.com/blockingioerror-errno-11-resource-temporarily-unavailable-pour-python-3-6/</link>
	<description>Du code, du cul</description>
	<lastBuildDate>Fri, 06 Sep 2019 09:34:15 +0000</lastBuildDate>
	<sy:updatePeriod>hourly</sy:updatePeriod>
	<sy:updateFrequency>1</sy:updateFrequency>
	<generator>https://wordpress.org/?v=4.9.7</generator>
	<item>
		<title>By: blackmoor</title>
		<link>http://sametmax.com/blockingioerror-errno-11-resource-temporarily-unavailable-pour-python-3-6/#comment-186032</link>
		<dc:creator><![CDATA[blackmoor]]></dc:creator>
		<pubDate>Fri, 03 Mar 2017 12:38:03 +0000</pubDate>
		<guid isPermaLink="false">http://sametmax.com/?p=22573#comment-186032</guid>
		<description><![CDATA[Petite typo:  au début --&#062; &quot;certains modules qui finissent pas déclencher par réaction&quot; --&#062; par déclencher
]]></description>
		<content:encoded><![CDATA[<p>Petite typo:  au début &#8211;&gt; &#8220;certains modules qui finissent pas déclencher par réaction&#8221; &#8211;&gt; par déclencher</p>
]]></content:encoded>
	</item>
	<item>
		<title>By: haypo</title>
		<link>http://sametmax.com/blockingioerror-errno-11-resource-temporarily-unavailable-pour-python-3-6/#comment-185948</link>
		<dc:creator><![CDATA[haypo]]></dc:creator>
		<pubDate>Tue, 28 Feb 2017 20:52:36 +0000</pubDate>
		<guid isPermaLink="false">http://sametmax.com/?p=22573#comment-185948</guid>
		<description><![CDATA[@Marc: Bah si t&#039;as Python 3.6.0, t&#039;as une version qui a le bug. Après pour reproduire le bug, il faut se lever de bonne heure car c&#039;est un très limite qui ne produit que sous certaines conditions. Lit la PEP 524 pour voir. L&#039;autre contournement est d&#039;utiliser Python 3.5 hein :-)
]]></description>
		<content:encoded><![CDATA[<p>@Marc: Bah si t&#8217;as Python 3.6.0, t&#8217;as une version qui a le bug. Après pour reproduire le bug, il faut se lever de bonne heure car c&#8217;est un très limite qui ne produit que sous certaines conditions. Lit la PEP 524 pour voir. L&#8217;autre contournement est d&#8217;utiliser Python 3.5 hein :-)</p>
]]></content:encoded>
	</item>
	<item>
		<title>By: Marc</title>
		<link>http://sametmax.com/blockingioerror-errno-11-resource-temporarily-unavailable-pour-python-3-6/#comment-185944</link>
		<dc:creator><![CDATA[Marc]]></dc:creator>
		<pubDate>Tue, 28 Feb 2017 16:05:02 +0000</pubDate>
		<guid isPermaLink="false">http://sametmax.com/?p=22573#comment-185944</guid>
		<description><![CDATA[Existe-t-il un bout de code ou autre permettant de constater que nous sommes confronté au problème sur nos environnements ?
]]></description>
		<content:encoded><![CDATA[<p>Existe-t-il un bout de code ou autre permettant de constater que nous sommes confronté au problème sur nos environnements ?</p>
]]></content:encoded>
	</item>
	<item>
		<title>By: Sam</title>
		<link>http://sametmax.com/blockingioerror-errno-11-resource-temporarily-unavailable-pour-python-3-6/#comment-185936</link>
		<dc:creator><![CDATA[Sam]]></dc:creator>
		<pubDate>Tue, 28 Feb 2017 13:35:19 +0000</pubDate>
		<guid isPermaLink="false">http://sametmax.com/?p=22573#comment-185936</guid>
		<description><![CDATA[&lt;p&gt;Ouai quand j&#039;ai vu la stack trace, je me suis souvenu qu&#039;un certain victor avait touché à random, et je t&#039;ai bien maudi. Mais bon, j&#039;ai fais bien pire comme connerie dans ma vie :)&lt;/p&gt;
]]></description>
		<content:encoded><![CDATA[<p>Ouai quand j&#8217;ai vu la stack trace, je me suis souvenu qu&#8217;un certain victor avait touché à random, et je t&#8217;ai bien maudi. Mais bon, j&#8217;ai fais bien pire comme connerie dans ma vie :)</p>
]]></content:encoded>
	</item>
	<item>
		<title>By: haypo</title>
		<link>http://sametmax.com/blockingioerror-errno-11-resource-temporarily-unavailable-pour-python-3-6/#comment-185934</link>
		<dc:creator><![CDATA[haypo]]></dc:creator>
		<pubDate>Tue, 28 Feb 2017 12:57:39 +0000</pubDate>
		<guid isPermaLink="false">http://sametmax.com/?p=22573#comment-185934</guid>
		<description><![CDATA[C&#039;est le bug http://bugs.python.org/issue29085 : régression de Python 3.6.0 connue et corrigée par https://github.com/python/cpython/commit/acc2f74ca991f6579f5b9055dfe885b9a8af4645 ... sauf que Python 3.6.1 n&#039;est prévu que pour le 2017-03-13 :-( Je n&#039;ai jamais compris pourquoi les releases managers attendent 3 mois après une version x.y.0 qui ajoute des milliers de changements et donc leur lot de régression. Bref, c&#039;est résolu dans qq. jours.

Le bug est que tu lances une application Python sur une système où le générateur de nombres aléatoires de Linux n&#039;est pas encore entièrement initialisé. C&#039;est censé prendre quelques secondes au boot, mais sur des VM mal configurée (hé oui), ça peut prendre de longues minutes... Voir https://haypo.github.io/pep-524-os-urandom-blocking.html qui explique la raison du changement (c&#039;est moi qui ait ajouté le bug dans le module random, désolé !).

Contournement pas sûr (je ne suis pas sûr que le RNG HAVEGE soit 100% sûr dans une VM) mais efficace : installer haveged pour &quot;corriger&quot; la VM, injecte de l&#039;entropie selon le &quot;bruit&quot; du CPU. Si tu héberges toi même tes VM, ajouter le pilote virtio-rng et là c&#039;est nickel.

Contournement en Python : lance &quot;python3.6 -S -c &#039;import os; os.urandom(1)&#039; &quot; avant ton application, la commande bloque jusqu&#039;à ce le RNG soit entièrement initialisé.

Allez, faut se dire que c&#039;est augmenter la sécurité de Python qu&#039;on s&#039;est payé ce bug ;-)
]]></description>
		<content:encoded><![CDATA[<p>C&#8217;est le bug <a href="http://bugs.python.org/issue29085" rel="nofollow">http://bugs.python.org/issue29085</a> : régression de Python 3.6.0 connue et corrigée par <a href="https://github.com/python/cpython/commit/acc2f74ca991f6579f5b9055dfe885b9a8af4645" rel="nofollow">https://github.com/python/cpython/commit/acc2f74ca991f6579f5b9055dfe885b9a8af4645</a> &#8230; sauf que Python 3.6.1 n&#8217;est prévu que pour le 2017-03-13 :-( Je n&#8217;ai jamais compris pourquoi les releases managers attendent 3 mois après une version x.y.0 qui ajoute des milliers de changements et donc leur lot de régression. Bref, c&#8217;est résolu dans qq. jours.</p>
<p>Le bug est que tu lances une application Python sur une système où le générateur de nombres aléatoires de Linux n&#8217;est pas encore entièrement initialisé. C&#8217;est censé prendre quelques secondes au boot, mais sur des VM mal configurée (hé oui), ça peut prendre de longues minutes&#8230; Voir <a href="https://haypo.github.io/pep-524-os-urandom-blocking.html" rel="nofollow">https://haypo.github.io/pep-524-os-urandom-blocking.html</a> qui explique la raison du changement (c&#8217;est moi qui ait ajouté le bug dans le module random, désolé !).</p>
<p>Contournement pas sûr (je ne suis pas sûr que le RNG HAVEGE soit 100% sûr dans une VM) mais efficace : installer haveged pour &#8220;corriger&#8221; la VM, injecte de l&#8217;entropie selon le &#8220;bruit&#8221; du CPU. Si tu héberges toi même tes VM, ajouter le pilote virtio-rng et là c&#8217;est nickel.</p>
<p>Contournement en Python : lance &#8220;python3.6 -S -c &#8216;import os; os.urandom(1)&#8217; &#8221; avant ton application, la commande bloque jusqu&#8217;à ce le RNG soit entièrement initialisé.</p>
<p>Allez, faut se dire que c&#8217;est augmenter la sécurité de Python qu&#8217;on s&#8217;est payé ce bug ;-)</p>
]]></content:encoded>
	</item>
	<item>
		<title>By: hackolite</title>
		<link>http://sametmax.com/blockingioerror-errno-11-resource-temporarily-unavailable-pour-python-3-6/#comment-185932</link>
		<dc:creator><![CDATA[hackolite]]></dc:creator>
		<pubDate>Tue, 28 Feb 2017 11:07:26 +0000</pubDate>
		<guid isPermaLink="false">http://sametmax.com/?p=22573#comment-185932</guid>
		<description><![CDATA[deadsnakes .... XD, prémonitoire.
]]></description>
		<content:encoded><![CDATA[<p>deadsnakes &#8230;. XD, prémonitoire.</p>
]]></content:encoded>
	</item>
</channel>
</rss>
